INFO 2025-06-07 02:19:20,499 autoreload 55718 8380145408 Watching for file changes with StatReloader
INFO 2025-06-07 02:19:28,168 basehttp 55718 6126481408 "GET /api/ HTTP/1.1" 200 631
INFO 2025-06-07 02:19:43,192 basehttp 55718 6126481408 "POST /api/auth/login/ HTTP/1.1" 200 584
INFO 2025-06-07 02:19:51,902 basehttp 55718 6126481408 "GET /api/products/ HTTP/1.1" 200 5703
INFO 2025-06-07 02:20:04,051 basehttp 55718 6143307776 "GET /api/dashboard/ HTTP/1.1" 200 232
INFO 2025-06-07 02:20:11,875 basehttp 55718 6160134144 "POST /api/auth/login/ HTTP/1.1" 200 591
INFO 2025-06-07 02:20:20,672 basehttp 55718 6176960512 "GET /api/dashboard/ HTTP/1.1" 200 146
INFO 2025-06-07 02:22:51,923 autoreload 55718 8380145408 /Users/evidenceejimone/daddy/backend/salesperson/models.py changed, reloading.
INFO 2025-06-07 02:22:52,104 autoreload 57940 8380145408 Watching for file changes with StatReloader
INFO 2025-06-07 02:23:06,431 autoreload 57940 8380145408 /Users/evidenceejimone/daddy/backend/salesperson/models.py changed, reloading.
INFO 2025-06-07 02:23:06,616 autoreload 57979 8380145408 Watching for file changes with StatReloader
WARNING 2025-06-07 02:23:26,683 log 58360 8380145408 Bad Request: /api/auth/login/
WARNING 2025-06-07 02:23:28,405 log 58360 8380145408 Bad Request: /api/payments/
WARNING 2025-06-07 02:23:28,719 log 58360 8380145408 Forbidden: /api/payments/
WARNING 2025-06-07 02:23:29,030 log 58360 8380145408 Bad Request: /api/payments/
WARNING 2025-06-07 02:23:29,652 log 58360 8380145408 Forbidden: /api/products/
WARNING 2025-06-07 02:23:30,277 log 58360 8380145408 Unauthorized: /api/products/
WARNING 2025-06-07 02:23:31,541 log 58360 8380145408 Forbidden: /api/reports/inventory/
ERROR 2025-06-07 02:23:32,211 log 58360 8380145408 Internal Server Error: /api/sales/
Traceback (most recent call last):
  File "/Users/evidenceejimone/daddy/venv/lib/python3.13/site-packages/django/core/handlers/exception.py", line 55, in inner
    response = get_response(request)
  File "/Users/evidenceejimone/daddy/venv/lib/python3.13/site-packages/django/core/handlers/base.py", line 197, in _get_response
    response = wrapped_callback(request, *callback_args, **callback_kwargs)
  File "/Users/evidenceejimone/daddy/venv/lib/python3.13/site-packages/django/views/decorators/csrf.py", line 65, in _view_wrapper
    return view_func(request, *args, **kwargs)
  File "/Users/evidenceejimone/daddy/venv/lib/python3.13/site-packages/django/views/generic/base.py", line 104, in view
    return self.dispatch(request, *args, **kwargs)
           ~~~~~~~~~~~~~^^^^^^^^^^^^^^^^^^^^^^^^^^
  File "/Users/evidenceejimone/daddy/venv/lib/python3.13/site-packages/rest_framework/views.py", line 515, in dispatch
    response = self.handle_exception(exc)
  File "/Users/evidenceejimone/daddy/venv/lib/python3.13/site-packages/rest_framework/views.py", line 475, in handle_exception
    self.raise_uncaught_exception(exc)
    ~~~~~~~~~~~~~~~~~~~~~~~~~~~~~^^^^^
  File "/Users/evidenceejimone/daddy/venv/lib/python3.13/site-packages/rest_framework/views.py", line 486, in raise_uncaught_exception
    raise exc
  File "/Users/evidenceejimone/daddy/venv/lib/python3.13/site-packages/rest_framework/views.py", line 512, in dispatch
    response = handler(request, *args, **kwargs)
  File "/Users/evidenceejimone/daddy/venv/lib/python3.13/site-packages/rest_framework/generics.py", line 246, in post
    return self.create(request, *args, **kwargs)
           ~~~~~~~~~~~^^^^^^^^^^^^^^^^^^^^^^^^^^
  File "/Users/evidenceejimone/daddy/venv/lib/python3.13/site-packages/rest_framework/mixins.py", line 18, in create
    serializer.is_valid(raise_exception=True)
    ~~~~~~~~~~~~~~~~~~~^^^^^^^^^^^^^^^^^^^^^^
  File "/Users/evidenceejimone/daddy/venv/lib/python3.13/site-packages/rest_framework/serializers.py", line 225, in is_valid
    self._validated_data = self.run_validation(self.initial_data)
                           ~~~~~~~~~~~~~~~~~~~^^^^^^^^^^^^^^^^^^^
  File "/Users/evidenceejimone/daddy/venv/lib/python3.13/site-packages/rest_framework/serializers.py", line 444, in run_validation
    value = self.to_internal_value(data)
  File "/Users/evidenceejimone/daddy/venv/lib/python3.13/site-packages/rest_framework/serializers.py", line 497, in to_internal_value
    for field in fields:
                 ^^^^^^
  File "/Users/evidenceejimone/daddy/venv/lib/python3.13/site-packages/rest_framework/serializers.py", line 380, in _writable_fields
    for field in self.fields.values():
                 ^^^^^^^^^^^
  File "/Users/evidenceejimone/daddy/venv/lib/python3.13/site-packages/django/utils/functional.py", line 47, in __get__
    res = instance.__dict__[self.name] = self.func(instance)
                                         ~~~~~~~~~^^^^^^^^^^
  File "/Users/evidenceejimone/daddy/venv/lib/python3.13/site-packages/rest_framework/serializers.py", line 374, in fields
    for key, value in self.get_fields().items():
                      ~~~~~~~~~~~~~~~^^
  File "/Users/evidenceejimone/daddy/venv/lib/python3.13/site-packages/rest_framework/serializers.py", line 1105, in get_fields
    field_class, field_kwargs = self.build_field(
                                ~~~~~~~~~~~~~~~~^
        source, info, model, depth
        ^^^^^^^^^^^^^^^^^^^^^^^^^^
    )
    ^
  File "/Users/evidenceejimone/daddy/venv/lib/python3.13/site-packages/rest_framework/serializers.py", line 1251, in build_field
    return self.build_unknown_field(field_name, model_class)
           ~~~~~~~~~~~~~~~~~~~~~~~~^^^^^^^^^^^^^^^^^^^^^^^^^
  File "/Users/evidenceejimone/daddy/venv/lib/python3.13/site-packages/rest_framework/serializers.py", line 1369, in build_unknown_field
    raise ImproperlyConfigured(
    ...<2 lines>...
    )
django.core.exceptions.ImproperlyConfigured: Field name `customer_contact` is not valid for model `Sale` in `salesperson.serializers.SaleSerializer`.
ERROR 2025-06-07 02:23:32,532 log 58360 8380145408 Internal Server Error: /api/sales/
Traceback (most recent call last):
  File "/Users/evidenceejimone/daddy/venv/lib/python3.13/site-packages/django/core/handlers/exception.py", line 55, in inner
    response = get_response(request)
  File "/Users/evidenceejimone/daddy/venv/lib/python3.13/site-packages/django/core/handlers/base.py", line 197, in _get_response
    response = wrapped_callback(request, *callback_args, **callback_kwargs)
  File "/Users/evidenceejimone/daddy/venv/lib/python3.13/site-packages/django/views/decorators/csrf.py", line 65, in _view_wrapper
    return view_func(request, *args, **kwargs)
  File "/Users/evidenceejimone/daddy/venv/lib/python3.13/site-packages/django/views/generic/base.py", line 104, in view
    return self.dispatch(request, *args, **kwargs)
           ~~~~~~~~~~~~~^^^^^^^^^^^^^^^^^^^^^^^^^^
  File "/Users/evidenceejimone/daddy/venv/lib/python3.13/site-packages/rest_framework/views.py", line 515, in dispatch
    response = self.handle_exception(exc)
  File "/Users/evidenceejimone/daddy/venv/lib/python3.13/site-packages/rest_framework/views.py", line 475, in handle_exception
    self.raise_uncaught_exception(exc)
    ~~~~~~~~~~~~~~~~~~~~~~~~~~~~~^^^^^
  File "/Users/evidenceejimone/daddy/venv/lib/python3.13/site-packages/rest_framework/views.py", line 486, in raise_uncaught_exception
    raise exc
  File "/Users/evidenceejimone/daddy/venv/lib/python3.13/site-packages/rest_framework/views.py", line 512, in dispatch
    response = handler(request, *args, **kwargs)
  File "/Users/evidenceejimone/daddy/venv/lib/python3.13/site-packages/rest_framework/generics.py", line 246, in post
    return self.create(request, *args, **kwargs)
           ~~~~~~~~~~~^^^^^^^^^^^^^^^^^^^^^^^^^^
  File "/Users/evidenceejimone/daddy/venv/lib/python3.13/site-packages/rest_framework/mixins.py", line 18, in create
    serializer.is_valid(raise_exception=True)
    ~~~~~~~~~~~~~~~~~~~^^^^^^^^^^^^^^^^^^^^^^
  File "/Users/evidenceejimone/daddy/venv/lib/python3.13/site-packages/rest_framework/serializers.py", line 225, in is_valid
    self._validated_data = self.run_validation(self.initial_data)
                           ~~~~~~~~~~~~~~~~~~~^^^^^^^^^^^^^^^^^^^
  File "/Users/evidenceejimone/daddy/venv/lib/python3.13/site-packages/rest_framework/serializers.py", line 444, in run_validation
    value = self.to_internal_value(data)
  File "/Users/evidenceejimone/daddy/venv/lib/python3.13/site-packages/rest_framework/serializers.py", line 497, in to_internal_value
    for field in fields:
                 ^^^^^^
  File "/Users/evidenceejimone/daddy/venv/lib/python3.13/site-packages/rest_framework/serializers.py", line 380, in _writable_fields
    for field in self.fields.values():
                 ^^^^^^^^^^^
  File "/Users/evidenceejimone/daddy/venv/lib/python3.13/site-packages/django/utils/functional.py", line 47, in __get__
    res = instance.__dict__[self.name] = self.func(instance)
                                         ~~~~~~~~~^^^^^^^^^^
  File "/Users/evidenceejimone/daddy/venv/lib/python3.13/site-packages/rest_framework/serializers.py", line 374, in fields
    for key, value in self.get_fields().items():
                      ~~~~~~~~~~~~~~~^^
  File "/Users/evidenceejimone/daddy/venv/lib/python3.13/site-packages/rest_framework/serializers.py", line 1105, in get_fields
    field_class, field_kwargs = self.build_field(
                                ~~~~~~~~~~~~~~~~^
        source, info, model, depth
        ^^^^^^^^^^^^^^^^^^^^^^^^^^
    )
    ^
  File "/Users/evidenceejimone/daddy/venv/lib/python3.13/site-packages/rest_framework/serializers.py", line 1251, in build_field
    return self.build_unknown_field(field_name, model_class)
           ~~~~~~~~~~~~~~~~~~~~~~~~^^^^^^^^^^^^^^^^^^^^^^^^^
  File "/Users/evidenceejimone/daddy/venv/lib/python3.13/site-packages/rest_framework/serializers.py", line 1369, in build_unknown_field
    raise ImproperlyConfigured(
    ...<2 lines>...
    )
django.core.exceptions.ImproperlyConfigured: Field name `customer_contact` is not valid for model `Sale` in `salesperson.serializers.SaleSerializer`.
ERROR 2025-06-07 02:23:32,860 log 58360 8380145408 Internal Server Error: /api/sales/
Traceback (most recent call last):
  File "/Users/evidenceejimone/daddy/venv/lib/python3.13/site-packages/django/core/handlers/exception.py", line 55, in inner
    response = get_response(request)
  File "/Users/evidenceejimone/daddy/venv/lib/python3.13/site-packages/django/core/handlers/base.py", line 197, in _get_response
    response = wrapped_callback(request, *callback_args, **callback_kwargs)
  File "/Users/evidenceejimone/daddy/venv/lib/python3.13/site-packages/django/views/decorators/csrf.py", line 65, in _view_wrapper
    return view_func(request, *args, **kwargs)
  File "/Users/evidenceejimone/daddy/venv/lib/python3.13/site-packages/django/views/generic/base.py", line 104, in view
    return self.dispatch(request, *args, **kwargs)
           ~~~~~~~~~~~~~^^^^^^^^^^^^^^^^^^^^^^^^^^
  File "/Users/evidenceejimone/daddy/venv/lib/python3.13/site-packages/rest_framework/views.py", line 515, in dispatch
    response = self.handle_exception(exc)
  File "/Users/evidenceejimone/daddy/venv/lib/python3.13/site-packages/rest_framework/views.py", line 475, in handle_exception
    self.raise_uncaught_exception(exc)
    ~~~~~~~~~~~~~~~~~~~~~~~~~~~~~^^^^^
  File "/Users/evidenceejimone/daddy/venv/lib/python3.13/site-packages/rest_framework/views.py", line 486, in raise_uncaught_exception
    raise exc
  File "/Users/evidenceejimone/daddy/venv/lib/python3.13/site-packages/rest_framework/views.py", line 512, in dispatch
    response = handler(request, *args, **kwargs)
  File "/Users/evidenceejimone/daddy/venv/lib/python3.13/site-packages/rest_framework/generics.py", line 243, in get
    return self.list(request, *args, **kwargs)
           ~~~~~~~~~^^^^^^^^^^^^^^^^^^^^^^^^^^
  File "/Users/evidenceejimone/daddy/venv/lib/python3.13/site-packages/rest_framework/mixins.py", line 40, in list
    page = self.paginate_queryset(queryset)
  File "/Users/evidenceejimone/daddy/venv/lib/python3.13/site-packages/rest_framework/generics.py", line 175, in paginate_queryset
    return self.paginator.paginate_queryset(queryset, self.request, view=self)
           ~~~~~~~~~~~~~~~~~~~~~~~~~~~~~~~~^^^^^^^^^^^^^^^^^^^^^^^^^^^^^^^^^^^
  File "/Users/evidenceejimone/daddy/venv/lib/python3.13/site-packages/rest_framework/pagination.py", line 222, in paginate_queryset
    return list(self.page)
  File "/Users/evidenceejimone/daddy/venv/lib/python3.13/site-packages/django/core/paginator.py", line 191, in __len__
    return len(self.object_list)
  File "/Users/evidenceejimone/daddy/venv/lib/python3.13/site-packages/django/db/models/query.py", line 366, in __len__
    self._fetch_all()
    ~~~~~~~~~~~~~~~^^
  File "/Users/evidenceejimone/daddy/venv/lib/python3.13/site-packages/django/db/models/query.py", line 1951, in _fetch_all
    self._prefetch_related_objects()
    ~~~~~~~~~~~~~~~~~~~~~~~~~~~~~~^^
  File "/Users/evidenceejimone/daddy/venv/lib/python3.13/site-packages/django/db/models/query.py", line 1328, in _prefetch_related_objects
    prefetch_related_objects(self._result_cache, *self._prefetch_related_lookups)
    ~~~~~~~~~~~~~~~~~~~~~~~~^^^^^^^^^^^^^^^^^^^^^^^^^^^^^^^^^^^^^^^^^^^^^^^^^^^^^
  File "/Users/evidenceejimone/daddy/venv/lib/python3.13/site-packages/django/db/models/query.py", line 2372, in prefetch_related_objects
    raise AttributeError(
    ...<7 lines>...
    )
AttributeError: Cannot find 'sale_items' on Sale object, 'sale_items__product' is an invalid parameter to prefetch_related()
WARNING 2025-06-07 02:23:33,950 log 58360 8380145408 Forbidden: /api/users/
INFO 2025-06-07 02:24:06,746 autoreload 57979 8380145408 /Users/evidenceejimone/daddy/backend/salesperson/serializers.py changed, reloading.
INFO 2025-06-07 02:24:06,979 autoreload 58492 8380145408 Watching for file changes with StatReloader
INFO 2025-06-07 02:24:21,346 autoreload 58492 8380145408 /Users/evidenceejimone/daddy/backend/salesperson/api_views.py changed, reloading.
INFO 2025-06-07 02:24:21,556 autoreload 58528 8380145408 Watching for file changes with StatReloader
INFO 2025-06-07 02:24:28,784 autoreload 58528 8380145408 /Users/evidenceejimone/daddy/backend/salesperson/api_views.py changed, reloading.
INFO 2025-06-07 02:24:28,969 autoreload 58549 8380145408 Watching for file changes with StatReloader
INFO 2025-06-07 02:25:04,743 autoreload 58549 8380145408 /Users/evidenceejimone/daddy/backend/salesperson/api_views.py changed, reloading.
INFO 2025-06-07 02:25:05,029 autoreload 58651 8380145408 Watching for file changes with StatReloader
WARNING 2025-06-07 02:27:10,451 log 59076 8380145408 Bad Request: /api/auth/login/
WARNING 2025-06-07 02:27:12,468 log 59076 8380145408 Forbidden: /api/payments/
WARNING 2025-06-07 02:27:12,781 log 59076 8380145408 Bad Request: /api/payments/
WARNING 2025-06-07 02:27:13,400 log 59076 8380145408 Forbidden: /api/products/
WARNING 2025-06-07 02:27:14,017 log 59076 8380145408 Unauthorized: /api/products/
WARNING 2025-06-07 02:27:15,255 log 59076 8380145408 Forbidden: /api/reports/inventory/
WARNING 2025-06-07 02:27:15,877 log 59076 8380145408 Bad Request: /api/sales/
WARNING 2025-06-07 02:27:16,188 log 59076 8380145408 Bad Request: /api/sales/
WARNING 2025-06-07 02:27:17,577 log 59076 8380145408 Forbidden: /api/users/
